
2024-06-04 17:49:39,892 - ERROR - 
Traceback (most recent call last):
  File "C:\Users\admin\AppData\Local\Programs\Python\Python37\lib\site-packages\urllib3\connectionpool.py", line 803, in urlopen
    **response_kw,
  File "C:\Users\admin\AppData\Local\Programs\Python\Python37\lib\site-packages\urllib3\connectionpool.py", line 492, in _make_request
    raise new_e
  File "C:\Users\admin\AppData\Local\Programs\Python\Python37\lib\site-packages\urllib3\connectionpool.py", line 468, in _make_request
    self._validate_conn(conn)
  File "C:\Users\admin\AppData\Local\Programs\Python\Python37\lib\site-packages\urllib3\connectionpool.py", line 1097, in _validate_conn
    conn.connect()
  File "C:\Users\admin\AppData\Local\Programs\Python\Python37\lib\site-packages\urllib3\connection.py", line 658, in connect
    assert_fingerprint=self.assert_fingerprint,
  File "C:\Users\admin\AppData\Local\Programs\Python\Python37\lib\site-packages\urllib3\connection.py", line 793, in _ssl_wrap_socket_and_match_hostname
    tls_in_tls=tls_in_tls,
  File "C:\Users\admin\AppData\Local\Programs\Python\Python37\lib\site-packages\urllib3\util\ssl_.py", line 471, in ssl_wrap_socket
    ssl_sock = _ssl_wrap_socket_impl(sock, context, tls_in_tls, server_hostname)
  File "C:\Users\admin\AppData\Local\Programs\Python\Python37\lib\site-packages\urllib3\util\ssl_.py", line 515, in _ssl_wrap_socket_impl
    return ssl_context.wrap_socket(sock, server_hostname=server_hostname)
  File "C:\Users\admin\AppData\Local\Programs\Python\Python37\lib\ssl.py", line 423, in wrap_socket
    session=session
  File "C:\Users\admin\AppData\Local\Programs\Python\Python37\lib\ssl.py", line 870, in _create
    self.do_handshake()
  File "C:\Users\admin\AppData\Local\Programs\Python\Python37\lib\ssl.py", line 1139, in do_handshake
    self._sslobj.do_handshake()
ConnectionResetError: [WinError 10054] 远程主机强迫关闭了一个现有的连接。

During handling of the above exception, another exception occurred:

Traceback (most recent call last):
  File "C:\Users\admin\AppData\Local\Programs\Python\Python37\lib\site-packages\requests\adapters.py", line 497, in send
    chunked=chunked,
  File "C:\Users\admin\AppData\Local\Programs\Python\Python37\lib\site-packages\urllib3\connectionpool.py", line 846, in urlopen
    method, url, error=new_e, _pool=self, _stacktrace=sys.exc_info()[2]
  File "C:\Users\admin\AppData\Local\Programs\Python\Python37\lib\site-packages\urllib3\util\retry.py", line 470, in increment
    raise reraise(type(error), error, _stacktrace)
  File "C:\Users\admin\AppData\Local\Programs\Python\Python37\lib\site-packages\urllib3\util\util.py", line 38, in reraise
    raise value.with_traceback(tb)
  File "C:\Users\admin\AppData\Local\Programs\Python\Python37\lib\site-packages\urllib3\connectionpool.py", line 803, in urlopen
    **response_kw,
  File "C:\Users\admin\AppData\Local\Programs\Python\Python37\lib\site-packages\urllib3\connectionpool.py", line 492, in _make_request
    raise new_e
  File "C:\Users\admin\AppData\Local\Programs\Python\Python37\lib\site-packages\urllib3\connectionpool.py", line 468, in _make_request
    self._validate_conn(conn)
  File "C:\Users\admin\AppData\Local\Programs\Python\Python37\lib\site-packages\urllib3\connectionpool.py", line 1097, in _validate_conn
    conn.connect()
  File "C:\Users\admin\AppData\Local\Programs\Python\Python37\lib\site-packages\urllib3\connection.py", line 658, in connect
    assert_fingerprint=self.assert_fingerprint,
  File "C:\Users\admin\AppData\Local\Programs\Python\Python37\lib\site-packages\urllib3\connection.py", line 793, in _ssl_wrap_socket_and_match_hostname
    tls_in_tls=tls_in_tls,
  File "C:\Users\admin\AppData\Local\Programs\Python\Python37\lib\site-packages\urllib3\util\ssl_.py", line 471, in ssl_wrap_socket
    ssl_sock = _ssl_wrap_socket_impl(sock, context, tls_in_tls, server_hostname)
  File "C:\Users\admin\AppData\Local\Programs\Python\Python37\lib\site-packages\urllib3\util\ssl_.py", line 515, in _ssl_wrap_socket_impl
    return ssl_context.wrap_socket(sock, server_hostname=server_hostname)
  File "C:\Users\admin\AppData\Local\Programs\Python\Python37\lib\ssl.py", line 423, in wrap_socket
    session=session
  File "C:\Users\admin\AppData\Local\Programs\Python\Python37\lib\ssl.py", line 870, in _create
    self.do_handshake()
  File "C:\Users\admin\AppData\Local\Programs\Python\Python37\lib\ssl.py", line 1139, in do_handshake
    self._sslobj.do_handshake()
urllib3.exceptions.ProtocolError: ('Connection aborted.', ConnectionResetError(10054, '远程主机强迫关闭了一个现有的连接。', None, 10054, None))

During handling of the above exception, another exception occurred:

Traceback (most recent call last):
  File "main.py", line 158, in <module>
    main()
  File "main.py", line 153, in main
    res_json = generateJSON()
  File "main.py", line 27, in generateJSON
    res = requests.get(url).json()
  File "C:\Users\admin\AppData\Local\Programs\Python\Python37\lib\site-packages\requests\api.py", line 73, in get
    return request("get", url, params=params, **kwargs)
  File "C:\Users\admin\AppData\Local\Programs\Python\Python37\lib\site-packages\requests\api.py", line 59, in request
    return session.request(method=method, url=url, **kwargs)
  File "C:\Users\admin\AppData\Local\Programs\Python\Python37\lib\site-packages\requests\sessions.py", line 589, in request
    resp = self.send(prep, **send_kwargs)
  File "C:\Users\admin\AppData\Local\Programs\Python\Python37\lib\site-packages\requests\sessions.py", line 703, in send
    r = adapter.send(request, **kwargs)
  File "C:\Users\admin\AppData\Local\Programs\Python\Python37\lib\site-packages\requests\adapters.py", line 501, in send
    raise ConnectionError(err, request=request)
requests.exceptions.ConnectionError: ('Connection aborted.', ConnectionResetError(10054, '远程主机强迫关闭了一个现有的连接。', None, 10054, None))

2024-06-04 17:51:42,737 - INFO - 200------更新成功
